<?xml version="1.0"?>
<sdf version="1.10">
  <model name="skywalker_x8">
    <pose>0 0 0.246 0 0 0</pose>
    
    <!-- Base Link: Inertial properties updated based on jsbsim -->
    <link name="base_link">
      <pose>0 0 0 0 0 0</pose>
      <inertial>
        <pose>0 0 0 0 0 0</pose>
        <!-- jsbsim empty weight ~7.42 lbs → 3.4 kg -->
        <mass>3.4</mass>
        <inertia>
          <!-- Converted from jsbsim mass_balance (slug*ft² converted to kg*m²) -->
          <ixx>0.335</ixx>
          <ixy>0</ixy>
          <ixz>-0.029</ixz>
          <iyy>0.14</iyy>
          <iyz>0</iyz>
          <izz>0.400</izz>
        </inertia>
      </inertial>
      
      <collision name="base_link_collision">
        <pose>0 0 -0.07 0 0 0</pose>
        <geometry>
          <box>
            <size>0.55 2.144 0.05</size>
          </box>
        </geometry>
        <surface>
          <contact>
            <ode>
              <kp>100000</kp>
              <kd>1.0</kd>
              <max_vel>0.1</max_vel>
              <min_depth>0.001</min_depth>
            </ode>
          </contact>
          <friction>
            <ode/>
          </friction>
        </surface>
      </collision>
      
      <visual name="base_link_visual">
        <pose>0.53 -1.072 -0.1 1.5708 0 3.1416</pose>
        <geometry>
          <mesh>
            <scale>0.001 0.001 0.001</scale>
            <uri>model://standard_vtol/meshes/x8_wing.dae</uri>
          </mesh>
        </geometry>
        <material>
          <ambient>0.175 0.175 0.175 1.0</ambient>
          <diffuse>0.175 0.175 0.175 1.0</diffuse>
        </material>
      </visual>
      
      <!-- Sensors remain as before -->
      <sensor name="imu_sensor" type="imu">
        <always_on>1</always_on>
        <update_rate>250</update_rate>
        <imu>
          <angular_velocity>
            <x>
              <noise type="gaussian">
                <mean>0</mean>
                <stddev>0.0003394</stddev>
                <dynamic_bias_stddev>3.8785e-05</dynamic_bias_stddev>
                <dynamic_bias_correlation_time>1000</dynamic_bias_correlation_time>
              </noise>
            </x>
            <y>
              <noise type="gaussian">
                <mean>0</mean>
                <stddev>0.0003394</stddev>
                <dynamic_bias_stddev>3.8785e-05</dynamic_bias_stddev>
                <dynamic_bias_correlation_time>1000</dynamic_bias_correlation_time>
              </noise>
            </y>
            <z>
              <noise type="gaussian">
                <mean>0</mean>
                <stddev>0.0003394</stddev>
                <dynamic_bias_stddev>3.8785e-05</dynamic_bias_stddev>
                <dynamic_bias_correlation_time>1000</dynamic_bias_correlation_time>
              </noise>
            </z>
          </angular_velocity>
          <linear_acceleration>
            <x>
              <noise type="gaussian">
                <mean>0</mean>
                <stddev>0.004</stddev>
                <dynamic_bias_stddev>0.006</dynamic_bias_stddev>
                <dynamic_bias_correlation_time>300</dynamic_bias_correlation_time>
              </noise>
            </x>
            <y>
              <noise type="gaussian">
                <mean>0</mean>
                <stddev>0.004</stddev>
                <dynamic_bias_stddev>0.006</dynamic_bias_stddev>
                <dynamic_bias_correlation_time>300</dynamic_bias_correlation_time>
              </noise>
            </y>
            <z>
              <noise type="gaussian">
                <mean>0</mean>
                <stddev>0.004</stddev>
                <dynamic_bias_stddev>0.006</dynamic_bias_stddev>
                <dynamic_bias_correlation_time>300</dynamic_bias_correlation_time>
              </noise>
            </z>
          </linear_acceleration>
        </imu>
      </sensor>
      
      <sensor name="air_pressure_sensor" type="air_pressure">
        <always_on>1</always_on>
        <update_rate>50</update_rate>
        <air_pressure>
          <pressure>
            <noise type="gaussian">
              <mean>0</mean>
              <stddev>0.01</stddev>
            </noise>
          </pressure>
        </air_pressure>
      </sensor>
      
      <sensor name="navsat_sensor" type="navsat">
        <always_on>1</always_on>
        <update_rate>30</update_rate>
      </sensor>
      
      <sensor name="magnetometer_sensor" type="magnetometer">
        <always_on>1</always_on>
        <update_rate>50</update_rate>
        <magnetometer>
          <x>
            <noise type="gaussian">
              <mean>0</mean>
              <stddev>0.02</stddev>
            </noise>
          </x>
          <y>
            <noise type="gaussian">
              <mean>0</mean>
              <stddev>0.02</stddev>
            </noise>
          </y>
          <z>
            <noise type="gaussian">
              <mean>0</mean>
              <stddev>0.02</stddev>
            </noise>
          </z>
        </magnetometer>
      </sensor>
      
      <gravity>1</gravity>
      <velocity_decay/>
      <self_collide>0</self_collide>
    </link>
    
    <!-- Rotor pusher (single prop for forward thrust) remains unchanged -->
    <link name="rotor_pusher">
      <pose>-0.22 0 0.0 0 1.57 0</pose>
      <inertial>
        <pose>0 0 0 0 0 0</pose>
        <mass>0.005</mass>
        <inertia>
          <ixx>9.75e-07</ixx>
          <ixy>0</ixy>
          <ixz>0</ixz>
          <iyy>0.000166704</iyy>
          <iyz>0</iyz>
          <izz>0.000167604</izz>
        </inertia>
      </inertial>
      <collision name="rotor_pusher_collision">
        <pose>0.0 0 -0.04 0 0 0</pose>
        <geometry>
          <cylinder>
            <length>0.005</length>
            <radius>0.06</radius>
          </cylinder>
        </geometry>
        <surface>
          <contact>
            <ode/>
          </contact>
          <friction>
            <ode/>
          </friction>
        </surface>
      </collision>
      <visual name="rotor_pusher_visual">
        <pose>0 0 -0.04 0 0 0</pose>
        <geometry>
          <mesh>
            <scale>0.8 0.8 0.8</scale>
            <uri>model://standard_vtol/meshes/iris_prop_ccw.dae</uri>
          </mesh>
        </geometry>
        <material>
          <ambient>0 0 1 1.0</ambient>
          <diffuse>0 0 1 1.0</diffuse>
        </material>
      </visual>
      <gravity>1</gravity>
      <velocity_decay/>
      <self_collide>0</self_collide>
    </link>
    
    <!-- Joint connecting rotor pusher to base_link -->
    <joint name="rotor_pusher_joint" type="revolute">
      <pose>0.0 0 0.0 0 -1.57 0</pose>
      <parent>base_link</parent>
      <child>rotor_pusher</child>
      <axis>
        <xyz>1 0 0</xyz>
        <limit>
          <lower>-1e+16</lower>
          <upper>1e+16</upper>
        </limit>
        <dynamics>
          <spring_reference>0</spring_reference>
          <spring_stiffness>0</spring_stiffness>
          <damping>0.002</damping>
        </dynamics>
      </axis>
    </joint>
    
    <!-- Fixed-wing control surfaces (using same structure as before) -->
    <link name="left_elevon">
      <inertial>
        <mass>1e-8</mass>
        <inertia>
          <ixx>1e-6</ixx>
          <ixy>0</ixy>
          <iyy>1e-6</iyy>
          <ixz>0</ixz>
          <iyz>0</iyz>
          <izz>1e-6</izz>
        </inertia>
        <pose>0 0.3 0 0 0 0</pose>
      </inertial>
      <visual name="left_elevon_visual">
        <pose>-0.105 0.004 -0.034 1.5708 0 3.1416</pose>
        <geometry>
          <mesh>
            <scale>0.001 0.001 0.001</scale>
            <uri>model://standard_vtol/meshes/x8_elevon_left.dae</uri>
          </mesh>
        </geometry>
        <material>
          <ambient>0 0 1 1.0</ambient>
          <diffuse>0 0 1 1.0</diffuse>
        </material>
      </visual>
    </link>
    
    <link name="right_elevon">
      <inertial>
        <mass>1e-8</mass>
        <inertia>
          <ixx>1e-6</ixx>
          <ixy>0</ixy>
          <iyy>1e-6</iyy>
          <ixz>0</ixz>
          <iyz>0</iyz>
          <izz>1e-6</izz>
        </inertia>
        <pose>0 -0.6 0 0 0 0</pose>
      </inertial>
      <visual name="right_elevon_visual">
        <pose>0.281 -1.032 -0.034 1.5708 0 3.1416</pose>
        <geometry>
          <mesh>
            <scale>0.001 0.001 0.001</scale>
            <uri>model://standard_vtol/meshes/x8_elevon_right.dae</uri>
          </mesh>
        </geometry>
        <material>
          <ambient>0 0 1 1.0</ambient>
          <diffuse>0 0 1 1.0</diffuse>
        </material>
      </visual>
    </link>
    
    <link name="elevator">
      <inertial>
        <mass>1e-8</mass>
        <inertia>
          <ixx>1e-6</ixx>
          <ixy>0</ixy>
          <iyy>1e-6</iyy>
          <ixz>0</ixz>
          <iyz>0</iyz>
          <izz>1e-6</izz>
        </inertia>
        <pose>-0.5 0 0 0 0 0</pose>
      </inertial>
    </link>
    
    <!-- Joints for control surfaces -->
    <joint name="servo_0" type="revolute">
      <parent>base_link</parent>
      <child>left_elevon</child>
      <pose>-0.18 0.6 -0.005 0 0 0.265</pose>
      <axis>
        <xyz>0 1 0</xyz>
        <limit>
          <lower>-0.78</lower>
          <upper>0.78</upper>
        </limit>
        <dynamics>
          <damping>1.0</damping>
        </dynamics>
      </axis>
      <physics>
        <ode>
          <implicit_spring_damper>1</implicit_spring_damper>
        </ode>
      </physics>
    </joint>
    
    <joint name="servo_1" type="revolute">
      <parent>base_link</parent>
      <child>right_elevon</child>
      <pose>-0.18 -0.6 -0.005 0 0 -0.265</pose>
      <axis>
        <xyz>0 1 0</xyz>
        <limit>
          <lower>-0.78</lower>
          <upper>0.78</upper>
        </limit>
        <dynamics>
          <damping>1.0</damping>
        </dynamics>
      </axis>
      <physics>
        <ode>
          <implicit_spring_damper>1</implicit_spring_damper>
        </ode>
      </physics>
    </joint>
    
    <joint name="servo_2" type="revolute">
      <parent>base_link</parent>
      <child>elevator</child>
      <pose>-0.5 0 0 0 0 0</pose>
      <axis>
        <xyz>0 1 0</xyz>
        <limit>
          <lower>-0.78</lower>
          <upper>0.78</upper>
        </limit>
        <dynamics>
          <damping>1.0</damping>
        </dynamics>
      </axis>
      <physics>
        <ode>
          <implicit_spring_damper>1</implicit_spring_damper>
        </ode>
      </physics>
    </joint>
    
    <!-- Lift-drag and control plugins -->
    <!-- Base wing: Updated aerodynamic parameters based on jsbsim -->
    <plugin filename="gz-sim-lift-drag-system" name="gz::sim::systems::LiftDrag">
      <a0>0.0867</a0>
      <cla>4.02</cla>
      <cda>0.010</cda>
      <cma>0.0</cma>
      <alpha_stall>0.34</alpha_stall>
      <cla_stall>-3.85</cla_stall>
      <cda_stall>-0.9234</cda_stall>
      <cp>0.01 0 0</cp>
      <area>0.75</area>
      <air_density>1.2041</air_density>
      <forward>1 0 0</forward>
      <upward>0 0 1</upward>
      <link_name>base_link</link_name>
    </plugin>
    
    <!-- Elevon and Elevator plugins remain similar (further tuning may be required) -->
    <plugin filename="gz-sim-lift-drag-system" name="gz::sim::systems::LiftDrag">
      <a0>0.15</a0>
      <cla>6.8</cla>
      <cda>0.06417</cda>
      <cma>0.0</cma>
      <alpha_stall>0.6391</alpha_stall>
      <cla_stall>-3.85</cla_stall>
      <cda_stall>-0.9234</cda_stall>
      <cp>-0.30 0.75 -0.005</cp>
      <area>0.10</area>
      <air_density>1.2041</air_density>
      <forward>1 0 0</forward>
      <upward>0 0 1</upward>
      <link_name>base_link</link_name>
      <control_joint_name>servo_0</control_joint_name>
      <control_joint_rad_to_cl>-5.0</control_joint_rad_to_cl>
    </plugin>
    
    <plugin filename="gz-sim-lift-drag-system" name="gz::sim::systems::LiftDrag">
      <a0>0.15</a0>
      <cla>6.8</cla>
      <cda>0.06417</cda>
      <cma>0.0</cma>
      <alpha_stall>0.6391</alpha_stall>
      <cla_stall>-3.85</cla_stall>
      <cda_stall>-0.9234</cda_stall>
      <cp>-0.30 -0.75 -0.005</cp>
      <area>0.10</area>
      <air_density>1.2041</air_density>
      <forward>1 0 0</forward>
      <upward>0 0 1</upward>
      <link_name>base_link</link_name>
      <control_joint_name>servo_1</control_joint_name>
      <control_joint_rad_to_cl>-5.0</control_joint_rad_to_cl>
    </plugin>
    
    <plugin filename="gz-sim-lift-drag-system" name="gz::sim::systems::LiftDrag">
      <a0>-0.2</a0>
      <cla>4.7528</cla>
      <cda>0.64171</cda>
      <cma>0.0</cma>
      <alpha_stall>0.3391</alpha_stall>
      <cla_stall>-3.85</cla_stall>
      <cda_stall>-0.9234</cda_stall>
      <cp>-0.5 0 0</cp>
      <area>0.01</area>
      <air_density>1.2041</air_density>
      <forward>1 0 0</forward>
      <upward>0 0 1</upward>
      <link_name>base_link</link_name>
      <control_joint_name>servo_2</control_joint_name>
      <control_joint_rad_to_cl>-12.0</control_joint_rad_to_cl>
    </plugin>
    
    <plugin filename="gz-sim-joint-position-controller-system" name="gz::sim::systems::JointPositionController">
      <joint_name>servo_0</joint_name>
      <sub_topic>servo_0</sub_topic>
    </plugin>
    <plugin filename="gz-sim-joint-position-controller-system" name="gz::sim::systems::JointPositionController">
      <joint_name>servo_1</joint_name>
      <sub_topic>servo_1</sub_topic>
    </plugin>
    <plugin filename="gz-sim-joint-position-controller-system" name="gz::sim::systems::JointPositionController">
      <joint_name>servo_2</joint_name>
      <sub_topic>servo_2</sub_topic>
    </plugin>
    
    <!-- Rotor pusher control plugins -->
    <plugin filename="gz-sim-apply-joint-force-system" name="gz::sim::systems::ApplyJointForce">
      <joint_name>rotor_pusher_joint</joint_name>
    </plugin>
    <plugin filename="gz-sim-joint-position-controller-system" name="gz::sim::systems::JointPositionController">
      <joint_name>rotor_pusher_joint</joint_name>
      <sub_topic>rotor_pusher</sub_topic>
    </plugin>
  </model>
</sdf>
